Workbook

Sheet pais_acogida
A1: Table 1 | Refugees, asylum-seekers, other people in need of international protection, internally displaced persons (IDPs), returnees (refugees and IDPs), stateless persons, and others of concern to UNHCR, by country/territory of asylum | end-2023
A2: All data are provisional and subject to change.
A3: Population statistics available at: | B3: https://www.unhcr.org/refugee-statistics/
A4: Solutions statistics available at: | B4: https://www.unhcr.org/refugee-statistics/
A5: Small values between zero and five have been rounded to multiples of five. A dash ("-") indicates that the value is zero, not available or not applicable.
B7: REFUGEES
A8: Country/territory of asylum1 | B8: Refugees2 | C8: People in refugee-like situations3 | D8: Total refugees and people in refugee-like situations | E8: Asylum-seekers (pending cases)4 | F8: Other people in need of international protection5 | G8: Returned refugees6 | H8: IDPs of concern to UNHCR7 | I8: Returned IDPs8 | J8: Persons under UNHCR's statelessness mandate9 | K8: Others of concern to UNHCR10 | L8: Total population of concern | M8: ISO 3 Code
A9: Afghanistan | B9: 34826 | C9: 0 | D9: 34826 | E9: 250 | F9: 0 | G9: 57530 | H9: 3222397 | I9: 31605 | J9: 0 | K9: 33712 | L9: 3380320 | M9: AFG | N9: Asia and the Pacific | O9: Asia
A10: Albania¹¹ | B10: 120 | C10: 4959 | D10: 5079 | E10: 8 | F10: 0 | G10: 0 | H10: 0 | I10: 0 | J10: 2018 | K10: 6 | L10: 7111 | M10: ALB | N10: Europe | O10: Europe
A11: Algeria¹² | B11: 98590 | C11: 0 | D11: 98590 | E11: 3601 | F11: 0 | G11: 0 | H11: 0 | I11: 0 | J11: 0 | K11: 0 | L11: 102191 | M11: DZA | N11: Middle East and North Africa | O11: Africa
A12: Angola | B12: 25174 | C12: 0 | D12: 25174 | E12: 30268 | F12: 0 | G12: 0 | H12: 0 | I12: 0 | J12: 0 | K12: 199 | L12: 55641 | M12: AGO | N12: Southern Africa | O12: Africa
A13: Argentina | B13: 4104 | C13: 0 | D13: 4104 | E13: 7129 | F13: 215541 | G13: 0 | H13: 0 | I13: 0 | J13: 22 | K13: 475 | L13: 227271 | M13: ARG | N13: Americas | O13: Latin America
A14: Armenia¹³ | B14: 145956 | C14: 4124 | D14: 150080 | E14: 615 | F14: 0 | G14: 0 | H14: 0 | I14: 0 | J14: 520 | K14: 0 | L14: 151215 | M14: ARM | N14: Europe | O14: Asia
A15: Aruba | B15: 0 | C15: 0 | D15: 0 | E15: 0 | F15: 17085 | G15: 0 | H15: 0 | I15: 0 | J15: 0 | K15: 0 | L15: 17085 | M15: ABW | N15: Americas | O15: North America and the Caribbean
A16: Australia¹⁴ | B16: 34502 | C16: 0 | D16: 34502 | E16: 82625 | F16: 0 | G16: 0 | H16: 0 | I16: 0 | J16: 8073 | K16: 1514 | L16: 120880 | M16: AUS | N16: Asia and the Pacific | O16: Oceania
A17: Austria | B17: 257811 | C17: 0 | D17: 257811 | E17: 38039 | F17: 0 | G17: 0 | H17: 0 | I17: 0 | J17: 3194 | K17: 0 | L17: 297234 | M17: AUT | N17: Europe | O17: Europe
A18: Azerbaijan | B18: 1570 | C18: 4201 | D18: 5771 | E18: 168 | F18: 0 | G18: 0 | H18: 657749 | I18: 0 | J18: 513 | K18: 0 | L18: 664201 | M18: AZE | N18: Europe | O18: Asia
A19: Bahamas¹⁵ | B19: 0 | C19: 0 | D19: 0 | E19: 31 | F19: 0 | G19: 0 | H19: 0 | I19: 0 | J19: 0 | K19: 723 | L19: 754 | M19: BHS | N19: Americas | O19: North America and the Caribbean
A20: Bahrain | B20: 254 | C20: 0 | D20: 254 | E20: 122 | F20: 0 | G20: 0 | H20: 0 | I20: 0 | J20: 0 | K20: 0 | L20: 376 | M20: BHR | N20: Middle East and North Africa | O20: Asia
... A186: Zimbabwe | B186: 10114 | C186: 0 | D186: 10114 | E186: 12451 | F186: 0 | G186: 0 | H186: 0 | I186: 0 | J186: 0 | K186: 1003 | L186: 23568 | M186: ZWE | N186: Southern Africa | O186: Africa
A187: Unknown/other | B187: 0 | C187: 0 | D187: 0 | E187: 0 | F187: 0 | G187: 6 | H187: 0 | I187: 0 | J187: 0 | K187: 0 | L187: 6 | M187: UKN
A188: Total | B188: =SUM(B9:B187) -> 25765364 | C188: =SUM(C9:C187) -> 5872044 | D188: =SUM(D9:D187) -> 31637408 | E188: =SUM(E9:E187) -> 6858499 | F188: =SUM(F9:F187) -> 5755363 | G188: =SUM(G9:G187) -> 1052074 | H188: =SUM(H9:H187) -> 63251367 | I188: =SUM(I9:I187) -> 5092064 | ... M188: =SUM(M9:M187) -> 0
A191: Notes
A192: The data are generally provided by governments, based on their own definitions and methods of data collection.
A193: 1 Country or territory of asylum or residence.
A194: 2 Refugees include individuals recognized under the 1951 Convention relating to the Status of Refugees, its 1967 Protocol, the 1969 Organization of African Unity (OAU) Convention Governing the Specific Aspects of Refugee Problems in Africa, the refugee definition contained in the 1984 Cartagena Declaration on Refugees as incorporated into national laws, those recognized in accordance with the UNHCR Statute, individuals granted complementary forms of protection, and those enjoying temporary protection. In the absence of Government figures, UNHCR has estimated the refugee population in many industrialized countries based on 10 years of individual asylum-seeker recognition. | P194: .
A195: 3 This category is descriptive in nature and includes groups of people who are outside their country or territory of origin and who face protection risks similar to those of refugees, but for whom refugee status has, for practical or other reasons, not been ascertained.
A196: 4 Asylum-seekers (with pending cases) are individuals who have sought international protection and whose claims for refugee status have not yet been determined. Those covered in this table refer to claimants whose individual applications were pending at the end of 2023, irrespective of when those claims may have been lodged.
A197: 5 People who are outside their country or territory of origin, typically because they have been forcibly displaced across international borders, who have not been reported under other categories (asylum seekers, refugees, people in refugee-like situations) but who likely need international protection, including protection against forced return, as well as access to basic services on a temporary or longer-term basis.
A198: 6 Refugees who have returned to their place of origin during the reporting year. Source: country of origin and asylum.
A199: 7 IDPs are persons or groups of persons who have been forced or obliged to flee or to leave their homes or places of habitual residence, in particular as a result of, or in order to avoid the effects of armed conflict, situations of generalized violence, violations of human rights or natural or human-made disasters, and who have not crossed an internationally recognized State border. For the purposes of UNHCR’s statistics, this population includes only conflict-generated IDPs to whom the Office extends protection and/or assistance.
A200: 8 IDPs of concern to UNHCR who have returned to their place of origin during the reporting year.
A201: 9 Refers to persons who are not considered as nationals by any State under the operation of its law. This category refers to persons who fall under the agency’s statelessness mandate because they are stateless according to this international definition, but data from some countries may also include persons with undetermined nationality. The figure reported includes stateless persons who are also refugees or asylum-seekers from Myanmar, IDPs in Myanmar, or others of concern to UNHCR. UNHCR’s statistical reporting generally follows a methodology that reports on one legal status for each person of concern only. However, due to the extraordinary size of the displaced stateless population from Myanmar, UNHCR considers it important to reflect the dual status that this population group possesses. Additional stateless refugees, asylum-seekers, and IDPs will be reported on as UNHCR continues to review and improve its reporting on stateless persons with a dual status.
A202: 10 Refers to individuals who do not necessarily fall directly into any of these groups above but to whom UNHCR has extended its protection and/or assistance services, based on humanitarian or other special grounds. This excludes host community that are assisted by UNHCR, who are reported separately.
A203: ¹¹ From various sources such as civil status offices, health institutions, schools, municipal child protection units, and social services, UNHCR estimates the number of people with undetermined nationality (at risk of statelessness).
A204: ¹² According to the Government of Algeria, there are an estimated 165,000 Sahrawi refugees in the Tindouf camps. Statistical data relating to refugees are entirely for humanitarian purposes. The total number of persons in need of humanitarian assistance services is estimated to be far higher than this figure.
A205: ¹³ In the South Caucasus region, 141,900 refugees fled to Armenia with most of them arriving after renewed armed conflict in Karabakh in September 2023.
A206: ¹⁴ The number of refugees in Australia has been revised using updated data on the number of residence permit holders with refugee status by the end of 2023, as received from the government.
... A250: ⁵⁸ The statelessness figure refers to stateless persons with permanent residence in Uzbekistan officially reported by the Government of Uzbekistan to UNHCR as of 31 December 2023. Information on other categories of statelessness is unavailable.

Sheet pais_acogida_UNHCR_bureaus
A1: UNHCR Bureaus | B1: Refugees2 | C1: People in refugee-like situations3 | D1: Total refugees and people in refugee-like situations | E1: Asylum-seekers (pending cases)4 | F1: Other people in need of international protection5 | G1: Returned refugees6 | H1: IDPs of concern to UNHCR7 | I1: Returned IDPs8 | J1: Persons under UNHCR's statelessness mandate9 | K1: Others of concern to UNHCR10 | L1: Total population of concern
A2: East and Horn of Africa, and Great Lakes | B2: =SUMIF(pais_acogida!$N$9:$N$187, $A2, pais_acogida!B$9:B$187) -> 4830730 | C2: =SUMIF(pais_acogida!$N$9:$N$187, $A2, pais_acogida!C$9:C$187) -> 0 | D2: =SUMIF(pais_acogida!$N$9:$N$187, $A2, pais_acogida!D$9:D$187) -> 4830730 | E2: =SUMIF(pais_acogida!$N$9:$N$187, $A2, pais_acogida!E$9:E$187) -> 382742 | F2: =SUMIF(pais_acogida!$N$9:$N$187, $A2, pais_acogida!F$9:F$187) -> 0 | G2: =SUMIF(pais_acogida!$N$9:$N$187, $A2, pais_acogida!G$9:G$187) -> 581131 | H2: =SUMIF(pais_acogida!$N$9:$N$187, $A2, pais_acogida!H$9:H$187) -> 16719267 | I2: =SUMIF(pais_acogida!$N$9:$N$187, $A2, pais_acogida!I$9:I$187) -> 534293 | ... L2: =SUMIF(pais_acogida!$N$9:$N$187, $A2, pais_acogida!L$9:L$187) -> 23235834
A3: Southern Africa | B3: =SUMIF(pais_acogida!$N$9:$N$187, $A3, pais_acogida!B$9:B$187) -> 806729 | C3: =SUMIF(pais_acogida!$N$9:$N$187, $A3, pais_acogida!C$9:C$187) -> 0 | D3: =SUMIF(pais_acogida!$N$9:$N$187, $A3, pais_acogida!D$9:D$187) -> 806729 | E3: =SUMIF(pais_acogida!$N$9:$N$187, $A3, pais_acogida!E$9:E$187) -> 186170 | F3: =SUMIF(pais_acogida!$N$9:$N$187, $A3, pais_acogida!F$9:F$187) -> 0 | G3: =SUMIF(pais_acogida!$N$9:$N$187, $A3, pais_acogida!G$9:G$187) -> 1808 | H3: =SUMIF(pais_acogida!$N$9:$N$187, $A3, pais_acogida!H$9:H$187) -> 6834554 | I3: =SUMIF(pais_acogida!$N$9:$N$187, $A3, pais_acogida!I$9:I$187) -> 2114080 | ... L3: =SUMIF(pais_acogida!$N$9:$N$187, $A3, pais_acogida!L$9:L$187) -> 9976212
A4: West and Central Africa | B4: =SUMIF(pais_acogida!$N$9:$N$187, $A4, pais_acogida!B$9:B$187) -> 2122973 | C4: =SUMIF(pais_acogida!$N$9:$N$187, $A4, pais_acogida!C$9:C$187) -> 0 | D4: =SUMIF(pais_acogida!$N$9:$N$187, $A4, pais_acogida!D$9:D$187) -> 2122973 | E4: =SUMIF(pais_acogida!$N$9:$N$187, $A4, pais_acogida!E$9:E$187) -> 177075 | F4: =SUMIF(pais_acogida!$N$9:$N$187, $A4, pais_acogida!F$9:F$187) -> 0 | G4: =SUMIF(pais_acogida!$N$9:$N$187, $A4, pais_acogida!G$9:G$187) -> 48855 | H4: =SUMIF(pais_acogida!$N$9:$N$187, $A4, pais_acogida!H$9:H$187) -> 7887599 | I4: =SUMIF(pais_acogida!$N$9:$N$187, $A4, pais_acogida!I$9:I$187) -> 455882 | ... L4: =SUMIF(pais_acogida!$N$9:$N$187, $A4, pais_acogida!L$9:L$187) -> 11783802
A5: Sub-Saharan Africa | B5: =SUM(B2:B4) -> 7760432 | C5: =SUM(C2:C4) -> 0 | D5: =SUM(D2:D4) -> 7760432 | E5: =SUM(E2:E4) -> 745987 | F5: =SUM(F2:F4) -> 0 | G5: =SUM(G2:G4) -> 631794 | H5: =SUM(H2:H4) -> 31441420 | I5: =SUM(I2:I4) -> 3104255 | ... L5: =SUM(L2:L4) -> 44995848
A6: Americas | B6: =SUMIF(pais_acogida!$N$9:$N$187, $A6, pais_acogida!B$9:B$187) -> 889711 | C6: =SUMIF(pais_acogida!$N$9:$N$187, $A6, pais_acogida!C$9:C$187) -> 196855 | D6: =SUMIF(pais_acogida!$N$9:$N$187, $A6, pais_acogida!D$9:D$187) -> 1086566 | E6: =SUMIF(pais_acogida!$N$9:$N$187, $A6, pais_acogida!E$9:E$187) -> 3954551 | F6: =SUMIF(pais_acogida!$N$9:$N$187, $A6, pais_acogida!F$9:F$187) -> 5755363 | G6: =SUMIF(pais_acogida!$N$9:$N$187, $A6, pais_acogida!G$9:G$187) -> 5 | H6: =SUMIF(pais_acogida!$N$9:$N$187, $A6, pais_acogida!H$9:H$187) -> 7813275 | I6: =SUMIF(pais_acogida!$N$9:$N$187, $A6, pais_acogida!I$9:I$187) -> 0 | ... L6: =SUMIF(pais_acogida!$N$9:$N$187, $A6, pais_acogida!L$9:L$187) -> 23011456
A7: Asia and the Pacific | B7: =SUMIF(pais_acogida!$N$9:$N$187, $A7, pais_acogida!B$9:B$187) -> 3617235 | C7: =SUMIF(pais_acogida!$N$9:$N$187, $A7, pais_acogida!C$9:C$187) -> 3815220 | D7: =SUMIF(pais_acogida!$N$9:$N$187, $A7, pais_acogida!D$9:D$187) -> 7432455 | E7: =SUMIF(pais_acogida!$N$9:$N$187, $A7, pais_acogida!E$9:E$187) -> 271573 | F7: =SUMIF(pais_acogida!$N$9:$N$187, $A7, pais_acogida!F$9:F$187) -> 0 | G7: =SUMIF(pais_acogida!$N$9:$N$187, $A7, pais_acogida!G$9:G$187) -> 57951 | H7: =SUMIF(pais_acogida!$N$9:$N$187, $A7, pais_acogida!H$9:H$187) -> 6039085 | I7: =SUMIF(pais_acogida!$N$9:$N$187, $A7, pais_acogida!I$9:I$187) -> 449303 | ... L7: =SUMIF(pais_acogida!$N$9:$N$187, $A7, pais_acogida!L$9:L$187) -> 15708655
A8: Europe | B8: =SUMIF(pais_acogida!$N$9:$N$187, $A8, pais_acogida!B$9:B$187) -> 11201166 | C8: =SUMIF(pais_acogida!$N$9:$N$187, $A8, pais_acogida!C$9:C$187) -> 1859969 | D8: =SUMIF(pais_acogida!$N$9:$N$187, $A8, pais_acogida!D$9:D$187) -> 13061135 | E8: =SUMIF(pais_acogida!$N$9:$N$187, $A8, pais_acogida!E$9:E$187) -> 1449236 | F8: =SUMIF(pais_acogida!$N$9:$N$187, $A8, pais_acogida!F$9:F$187) -> 0 | G8: =SUMIF(pais_acogida!$N$9:$N$187, $A8, pais_acogida!G$9:G$187) -> 324590 | H8: =SUMIF(pais_acogida!$N$9:$N$187, $A8, pais_acogida!H$9:H$187) -> 4943593 | I8: =SUMIF(pais_acogida!$N$9:$N$187, $A8, pais_acogida!I$9:I$187) -> 1318794 | ... L8: =SUMIF(pais_acogida!$N$9:$N$187, $A8, pais_acogida!L$9:L$187) -> 22503480
A9: Middle East and North Africa | B9: =SUMIF(pais_acogida!$N$9:$N$187, $A9, pais_acogida!B$9:B$187) -> 2296820 | C9: =SUMIF(pais_acogida!$N$9:$N$187, $A9, pais_acogida!C$9:C$187) -> 0 | D9: =SUMIF(pais_acogida!$N$9:$N$187, $A9, pais_acogida!D$9:D$187) -> 2296820 | E9: =SUMIF(pais_acogida!$N$9:$N$187, $A9, pais_acogida!E$9:E$187) -> 437152 | F9: =SUMIF(pais_acogida!$N$9:$N$187, $A9, pais_acogida!F$9:F$187) -> 0 | G9: =SUMIF(pais_acogida!$N$9:$N$187, $A9, pais_acogida!G$9:G$187) -> 37728 | H9: =SUMIF(pais_acogida!$N$9:$N$187, $A9, pais_acogida!H$9:H$187) -> 13013994 | I9: =SUMIF(pais_acogida!$N$9:$N$187, $A9, pais_acogida!I$9:I$187) -> 219712 | ... L9: =SUMIF(pais_acogida!$N$9:$N$187, $A9, pais_acogida!L$9:L$187) -> 16403404
A10: Various/Stateless | B10: =pais_acogida!B188-SUM(B5:B9) -> 0 | C10: =pais_acogida!C188-SUM(C5:C9) -> 0 | D10: =pais_acogida!D188-SUM(D5:D9) -> 0 | E10: =pais_acogida!E188-SUM(E5:E9) -> 0 | F10: =pais_acogida!F188-SUM(F5:F9) -> 0 | G10: =pais_acogida!G188-SUM(G5:G9) -> 6 | H10: =pais_acogida!H188-SUM(H5:H9) -> 0 | I10: =pais_acogida!I188-SUM(I5:I9) -> 0 | ... L10: =pais_acogida!L188-SUM(L5:L9) -> 6
A11: Total | B11: =SUM(B2:B9)-B5 -> 25765364 | C11: =SUM(C2:C9)-C5 -> 5872044 | D11: =SUM(D2:D9)-D5 -> 31637408 | E11: =SUM(E2:E9)-E5 -> 6858499 | F11: =SUM(F2:F9)-F5 -> 5755363 | G11: =SUM(G2:G10)-G5 -> 1052074 | H11: =SUM(H2:H9)-H5 -> 63251367 | I11: =SUM(I2:I9)-I5 -> 5092064 | J11: =SUM(J2:J9)-J5 -> 4358188 | K11: =SUM(K2:K9)-K5 -> 5945550 | L11: =SUM(L2:L10)-L5 -> 122622849

Sheet pais_acogida_UN_regions
A1: UN major regions | B1: Refugees2 | C1: People in refugee-like situations3 | D1: Total refugees and people in refugee-like situations | E1: Asylum-seekers (pending cases)4 | F1: Other people in need of international protection5 | G1: Returned refugees6 | H1: IDPs of concern to UNHCR7 | I1: Returned IDPs8 | J1: Persons under UNHCR's statelessness mandate9 | K1: Others of concern to UNHCR10 | L1: Total population of concern
A2: Africa | B2: =SUMIF(pais_acogida!$O$9:$O$187, $A2, pais_acogida!B$9:B$187) -> 8226204 | C2: =SUMIF(pais_acogida!$O$9:$O$187, $A2, pais_acogida!C$9:C$187) -> 0 | D2: =SUMIF(pais_acogida!$O$9:$O$187, $A2, pais_acogida!D$9:D$187) -> 8226204 | E2: =SUMIF(pais_acogida!$O$9:$O$187, $A2, pais_acogida!E$9:E$187) -> 1065029 | F2: =SUMIF(pais_acogida!$O$9:$O$187, $A2, pais_acogida!F$9:F$187) -> 0 | G2: =SUMIF(pais_acogida!$O$9:$O$187, $A2, pais_acogida!G$9:G$187) -> 631805 | H2: =SUMIF(pais_acogida!$O$9:$O$187, $A2, pais_acogida!H$9:H$187) -> 31567222 | I2: =SUMIF(pais_acogida!$O$9:$O$187, $A2, pais_acogida!I$9:I$187) -> 3141354 | ... L2: =SUMIF(pais_acogida!$O$9:$O$187, $A2, pais_acogida!L$9:L$187) -> 45943602
A3: Asia | B3: =SUMIF(pais_acogida!$O$9:$O$187, $A3, pais_acogida!B$9:B$187) -> 8845372 | C3: =SUMIF(pais_acogida!$O$9:$O$187, $A3, pais_acogida!C$9:C$187) -> 3843295 | D3: =SUMIF(pais_acogida!$O$9:$O$187, $A3, pais_acogida!D$9:D$187) -> 12688667 | E3: =SUMIF(pais_acogida!$O$9:$O$187, $A3, pais_acogida!E$9:E$187) -> 557470 | F3: =SUMIF(pais_acogida!$O$9:$O$187, $A3, pais_acogida!F$9:F$187) -> 0 | G3: =SUMIF(pais_acogida!$O$9:$O$187, $A3, pais_acogida!G$9:G$187) -> 95668 | H3: =SUMIF(pais_acogida!$O$9:$O$187, $A3, pais_acogida!H$9:H$187) -> 19784857 | I3: =SUMIF(pais_acogida!$O$9:$O$187, $A3, pais_acogida!I$9:I$187) -> 631916 | ... L3: =SUMIF(pais_acogida!$O$9:$O$187, $A3, pais_acogida!L$9:L$187) -> 35611325
A4: Europe | B4: =SUMIF(pais_acogida!$O$9:$O$187, $A4, pais_acogida!B$9:B$187) -> 7762200 | C4: =SUMIF(pais_acogida!$O$9:$O$187, $A4, pais_acogida!C$9:C$187) -> 1826894 | D4: =SUMIF(pais_acogida!$O$9:$O$187, $A4, pais_acogida!D$9:D$187) -> 9589094 | E4: =SUMIF(pais_acogida!$O$9:$O$187, $A4, pais_acogida!E$9:E$187) -> 1193669 | F4: =SUMIF(pais_acogida!$O$9:$O$187, $A4, pais_acogida!F$9:F$187) -> 0 | G4: =SUMIF(pais_acogida!$O$9:$O$187, $A4, pais_acogida!G$9:G$187) -> 324590 | H4: =SUMIF(pais_acogida!$O$9:$O$187, $A4, pais_acogida!H$9:H$187) -> 3990013 | I4: =SUMIF(pais_acogida!$O$9:$O$187, $A4, pais_acogida!I$9:I$187) -> 1318794 | ... L4: =SUMIF(pais_acogida!$O$9:$O$187, $A4, pais_acogida!L$9:L$187) -> 17820314
A5: Latin America | B5: =SUMIF(pais_acogida!$O$9:$O$187, $A5, pais_acogida!B$9:B$187) -> 381722 | C5: =SUMIF(pais_acogida!$O$9:$O$187, $A5, pais_acogida!C$9:C$187) -> 122075 | D5: =SUMIF(pais_acogida!$O$9:$O$187, $A5, pais_acogida!D$9:D$187) -> 503797 | E5: =SUMIF(pais_acogida!$O$9:$O$187, $A5, pais_acogida!E$9:E$187) -> 1119390 | F5: =SUMIF(pais_acogida!$O$9:$O$187, $A5, pais_acogida!F$9:F$187) -> 5572863 | G5: =SUMIF(pais_acogida!$O$9:$O$187, $A5, pais_acogida!G$9:G$187) -> 5 | H5: =SUMIF(pais_acogida!$O$9:$O$187, $A5, pais_acogida!H$9:H$187) -> 7499374 | I5: =SUMIF(pais_acogida!$O$9:$O$187, $A5, pais_acogida!I$9:I$187) -> 0 | ... L5: =SUMIF(pais_acogida!$O$9:$O$187, $A5, pais_acogida!L$9:L$187) -> 19090685
A6: North America and the Caribbean | B6: =SUMIF(pais_acogida!$O$9:$O$187, $A6, pais_acogida!B$9:B$187) -> 507989 | C6: =SUMIF(pais_acogida!$O$9:$O$187, $A6, pais_acogida!C$9:C$187) -> 74780 | D6: =SUMIF(pais_acogida!$O$9:$O$187, $A6, pais_acogida!D$9:D$187) -> 582769 | E6: =SUMIF(pais_acogida!$O$9:$O$187, $A6, pais_acogida!E$9:E$187) -> 2835161 | F6: =SUMIF(pais_acogida!$O$9:$O$187, $A6, pais_acogida!F$9:F$187) -> 182500 | G6: =SUMIF(pais_acogida!$O$9:$O$187, $A6, pais_acogida!G$9:G$187) -> 0 | H6: =SUMIF(pais_acogida!$O$9:$O$187, $A6, pais_acogida!H$9:H$187) -> 313901 | I6: =SUMIF(pais_acogida!$O$9:$O$187, $A6, pais_acogida!I$9:I$187) -> 0 | ... L6: =SUMIF(pais_acogida!$O$9:$O$187, $A6, pais_acogida!L$9:L$187) -> 3920771
A7: Oceania | B7: =SUMIF(pais_acogida!$O$9:$O$187, $A7, pais_acogida!B$9:B$187) -> 41877 | C7: =SUMIF(pais_acogida!$O$9:$O$187, $A7, pais_acogida!C$9:C$187) -> 5000 | D7: =SUMIF(pais_acogida!$O$9:$O$187, $A7, pais_acogida!D$9:D$187) -> 46877 | E7: =SUMIF(pais_acogida!$O$9:$O$187, $A7, pais_acogida!E$9:E$187) -> 87780 | F7: =SUMIF(pais_acogida!$O$9:$O$187, $A7, pais_acogida!F$9:F$187) -> 0 | G7: =SUMIF(pais_acogida!$O$9:$O$187, $A7, pais_acogida!G$9:G$187) -> 0 | H7: =SUMIF(pais_acogida!$O$9:$O$187, $A7, pais_acogida!H$9:H$187) -> 96000 | I7: =SUMIF(pais_acogida!$O$9:$O$187, $A7, pais_acogida!I$9:I$187) -> 0 | ... L7: =SUMIF(pais_acogida!$O$9:$O$187, $A7, pais_acogida!L$9:L$187) -> 236146
A8: Various/Stateless | B8: =pais_acogida!B188-SUM(B2:B7) -> 0 | C8: =pais_acogida!C188-SUM(C2:C7) -> 0 | D8: =pais_acogida!D188-SUM(D2:D7) -> 0 | E8: =pais_acogida!E188-SUM(E2:E7) -> 0 | F8: =pais_acogida!F188-SUM(F2:F7) -> 0 | G8: =pais_acogida!G188-SUM(G2:G7) -> 6 | H8: =pais_acogida!H188-SUM(H2:H7) -> 0 | I8: =pais_acogida!I188-SUM(I2:I7) -> 0 | ... L8: =pais_acogida!L188-SUM(L2:L7) -> 6
A9: Total | B9: =SUM(B2:B7) -> 25765364 | C9: =SUM(C2:C7) -> 5872044 | D9: =SUM(D2:D7) -> 31637408 | E9: =SUM(E2:E7) -> 6858499 | F9: =SUM(F2:F7) -> 5755363 | G9: =SUM(G2:G8) -> 1052074 | H9: =SUM(H2:H7) -> 63251367 | I9: =SUM(I2:I7) -> 5092064 | J9: =SUM(J2:J7) -> 4358188 | K9: =SUM(K2:K7) -> 5945550 | L9: =SUM(L2:L8) -> 122622849

Sheet pais_origen
A1: Table 2 | Refugees, asylum-seekers, other people in need of international protection, internally displaced persons (IDPs), returnees (refugees and IDPs), stateless persons, and others of concern to UNHCR, by country/territory of origin | end-2023
A2: All data are provisional and subject to change.
A3: Population statistics available at: | B3: https://www.unhcr.org/refugee-statistics/
A4: Solutions statistics available at: | B4: https://www.unhcr.org/refugee-statistics/
A5: Small values between zero and five have been rounded to multiples of five. A dash ("-") indicates that the value is zero, not available or not applicable.
A7: Origin1 | B7: Refugees 2 | C7: People in refugee-like situations3 | D7: Total refugees and people in refugee-like situations | E7: Asylum-seekers (pending cases)4 | F7: Other people in need of international protection5 | G7: Returned refugees6 | H7: IDPs of concern to UNHCR7 | I7: Returned IDPs8 | J7: Persons under UNHCR's statelessness mandate9 | K7: Others of concern to UNHCR10 | L7: Total population of concern | M7: ISO 3 Code
A8: Afghanistan | B8: 2751470 | C8: 3651674 | D8: 6403144 | E8: 296033 | F8: 0 | G8: 57530 | H8: 3222397 | I8: 31605 | J8: 0 | K8: 34534 | L8: 10045243 | M8: AFG | N8: Asia and the Pacific | O8: Asia
A9: Albania | B9: 21911 | C9: 8 | D9: 21919 | E9: 17539 | F9: 0 | G9: 0 | H9: 0 | I9: 0 | J9: 0 | K9: 0 | L9: 39458 | M9: ALB | N9: Europe | O9: Europe
A10: Algeria | B10: 7521 | C10: 108 | D10: 7629 | E10: 11330 | F10: 0 | G10: 0 | H10: 0 | I10: 0 | J10: 0 | K10: 48 | L10: 19007 | M10: DZA | N10: Middle East and North Africa | O10: Africa
A11: Andorra | B11: 0 | C11: 0 | D11: 0 | E11: 14 | F11: 0 | G11: 0 | H11: 0 | I11: 0 | J11: 0 | K11: 0 | L11: 14 | M11: AND | N11: Europe | O11: Europe
A12: Angola | B12: 11501 | C12: 5 | D12: 11506 | E12: 22824 | F12: 0 | G12: 0 | H12: 0 | I12: 0 | J12: 0 | K12: 13637 | L12: 47967 | M12: AGO | N12: Southern Africa | O12: Africa
A13: Anguilla | B13: 0 | C13: 0 | D13: 0 | E13: 5 | F13: 0 | G13: 0 | H13: 0 | I13: 0 | J13: 0 | K13: 0 | L13: 5 | M13: AIA | N13: Americas | O13: North America and the Caribbean
A14: Antigua and Barbuda | B14: 67 | C14: 0 | D14: 67 | E14: 51 | F14: 0 | G14: 0 | H14: 0 | I14: 0 | J14: 0 | K14: 0 | L14: 118 | M14: ATG | N14: Americas | O14: North America and the Caribbean
A15: Argentina | B15: 300 | C15: 0 | D15: 300 | E15: 4388 | F15: 0 | G15: 0 | H15: 0 | I15: 0 | J15: 0 | K15: 5 | L15: 4693 | M15: ARG | N15: Americas | O15: Latin America
A16: Armenia | B16: 14908 | C16: 164 | D16: 15072 | E16: 18378 | F16: 0 | G16: 0 | H16: 0 | I16: 0 | J16: 0 | K16: 8 | L16: 33458 | M16: ARM | N16: Europe | O16: Asia
A17: Australia | B17: 29 | C17: 0 | D17: 29 | E17: 68 | F17: 0 | G17: 0 | H17: 0 | I17: 0 | J17: 0 | K17: 0 | L17: 97 | M17: AUS | N17: Asia and the Pacific | O17: Oceania
A18: Austria | B18: 23 | C18: 0 | D18: 23 | E18: 30 | F18: 0 | G18: 0 | H18: 0 | I18: 0 | J18: 0 | K18: 0 | L18: 53 | M18: AUT | N18: Europe | O18: Europe
A19: Azerbaijan | B19: 157733 | C19: 365 | D19: 158098 | E19: 6777 | F19: 0 | G19: 0 | H19: 657749 | I19: 0 | J19: 0 | K19: 0 | L19: 822624 | M19: AZE | N19: Europe | O19: Asia
... A185: Thailand | B185: 222 | C185: 0 | D185: 222 | E185: 3371 | F185: 0 | G185: 0 | H185: 0 | I185: 0 | J185: 0 | K185: 0 | L185: 3593 | M185: THA | N185: Asia and the Pacific | O185: Asia
A186: Tibetan | B186: 12575 | C186: 0 | D186: 12575 | E186: 0 | F186: 0 | G186: 0 | H186: 0 | I186: 0 | J186: 0 | K186: 14 | L186: 12589 | N186: Asia and the Pacific | O186: Asia
A187: Timor-Leste | B187: 0 | C187: 0 | D187: 0 | E187: 1085 | F187: 0 | G187: 0 | H187: 0 | I187: 0 | J187: 0 | K187: 0 | L187: 1085 | M187: TLS | N187: Asia and the Pacific | O187: Asia
A188: Togo | B188: 7955 | C188: 0 | D188: 7955 | E188: 8192 | F188: 0 | G188: 0 | H188: 9680 | I188: 0 | J188: 0 | K188: 0 | L188: 25827 | M188: TGO | N188: West and Central Africa | O188: Africa
A189: Tonga | B189: 41 | C189: 0 | D189: 41 | E189: 1327 | F189: 0 | G189: 0 | H189: 0 | I189: 0 | J189: 0 | K189: 0 | L189: 1368 | M189: TON | N189: Asia and the Pacific | O189: Oceania
A190: Trinidad and Tobago | B190: 351 | C190: 0 | D190: 351 | E190: 819 | F190: 0 | G190: 0 | H190: 0 | I190: 0 | J190: 0 | K190: 1040 | L190: 2210 | M190: TTO | N190: Americas | O190: North America and the Caribbean
A191: Tunisia | B191: 2742 | C191: 58 | D191: 2800 | E191: 9194 | F191: 0 | G191: 0 | H191: 0 | I191: 0 | J191: 0 | K191: 10 | L191: 12004 | M191: TUN | N191: Middle East and North Africa | O191: Africa
A192: Turkmenistan | B192: 1457 | C192: 391 | D192: 1848 | E192: 1833 | F192: 0 | G192: 0 | H192: 0 | I192: 0 | J192: 0 | K192: 0 | L192: 3681 | M192: TKM | N192: Asia and the Pacific | O192: Asia
A193: Turks and Caicos Islands | B193: 19 | C193: 0 | D193: 19 | E193: 6 | F193: 0 | G193: 0 | H193: 0 | I193: 0 | J193: 0 | K193: 0 | L193: 25 | M193: TCA | N193: Americas | O193: North America and the Caribbean
A194: Tuvalu | B194: 0 | C194: 0 | D194: 0 | E194: 5 | F194: 0 | G194: 0 | H194: 0 | I194: 0 | J194: 0 | K194: 0 | L194: 5 | M194: TUV | N194: Asia and the Pacific | O194: Oceania
A195: Türkiye | B195: 127504 | C195: 234 | D195: 127738 | E195: 153142 | F195: 0 | G195: 0 | H195: 0 | I195: 0 | J195: 0 | K195: 467 | L195: 281347 | M195: TUR | N195: Europe | O195: Asia
A196: Uganda | B196: 8360 | C196: 16 | D196: 8376 | E196: 14989 | F196: 0 | G196: 0 | H196: 0 | I196: 0 | J196: 0 | K196: 5 | L196: 23370 | M196: UGA | N196: East and Horn of Africa, and Great Lakes | O196: Africa
A197: Ukraine¹⁴ | B197: 4057674 | C197: 1902688 | D197: 5960362 | E197: 33988 | F197: 0 | G197: 324573 | H197: 3689000 | I197: 1318680 | J197: 0 | K197: 988425 | L197: 12315028 | M197: UKR | N197: Europe | O197: Europe
A198: United Arab Emirates | B198: 229 | C198: 0 | D198: 229 | E198: 171 | F198: 0 | G198: 0 | H198: 0 | I198: 0 | J198: 0 | K198: 0 | L198: 400 | M198: ARE | N198: Middle East and North Africa | O198: Asia
... A210: Zimbabwe | B210: 7438 | C210: 22 | D210: 7460 | E210: 9125 | F210: 0 | G210: 0 | H210: 0 | I210: 0 | J210: 0 | K210: 170 | L210: 16755 | M210: ZWE | N210: Southern Africa | O210: Africa
A211: Stateless | B211: 51899 | C211: 13 | D211: 51912 | E211: 5344 | F211: 0 | G211: 6 | H211: 0 | I211: 0 | J211: 4358188 | K211: 8998 | L211: 3096784 | M211: STA
A212: Various/unknown | B212: 106180 | C212: 73072 | D212: 179252 | E212: 95550 | F212: 0 | G212: 0 | H212: 0 | I212: 0 | J212: 0 | K212: 165807 | L212: 440609 | M212: UKN
A213: Total | B213: =SUM(B8:B212) -> 25765364 | C213: =SUM(C8:C212) -> 5872044 | D213: =SUM(D8:D212) -> 31637408 | E213: =SUM(E8:E212) -> 6858499 | F213: =SUM(F8:F212) -> 5755363 | G213: =SUM(G8:G212) -> 1052074 | H213: =SUM(H8:H212) -> 63251367 | I213: =SUM(I8:I212) -> 5092064 | ... L213: =SUM(L8:L212) -> 122622849
A216: Notes
A217: The data are generally provided by governments, based on their own definitions and methods of data collection.
A218: 1 Country or territory of origin.
A219: 2 Refugees include individuals recognized under the 1951 Convention relating to the Status of Refugees, its 1967 Protocol, the 1969 Organization of African Unity (OAU) Convention Governing the Specific Aspects of Refugee Problems in Africa, the refugee definition contained in the 1984 Cartagena Declaration on Refugees as incorporated into national laws, those recognized in accordance with the UNHCR Statute, individuals granted complementary forms of protection, and those enjoying temporary protection. In the absence of Government figures, UNHCR has estimated the refugee population in many industrialized countries based on 10 years of individual asylum-seeker recognition.
...

Sheet pais_origen_UNHCR_bureaus
A1: UNHCR Bureaus | B1: Refugees 2 | C1: People in refugee-like situations3 | D1: Total refugees and people in refugee-like situations | E1: Asylum-seekers (pending cases)4 | F1: Other people in need of international protection5 | G1: Returned refugees6 | H1: IDPs of concern to UNHCR7 | I1: Returned IDPs8 | J1: Persons under UNHCR's statelessness mandate9 | K1: Others of concern to UNHCR10 | L1: Total population of concern
A2: East and Horn of Africa, and Great Lakes | B2: =SUMIF(pais_origen!$N$8:$N$212, $A2, pais_origen!B$8:B$212) -> 5938419 | C2: =SUMIF(pais_origen!$N$8:$N$212, $A2, pais_origen!C$8:C$212) -> 194 | D2: =SUMIF(pais_origen!$N$8:$N$212, $A2, pais_origen!D$8:D$212) -> 5938613 | E2: =SUMIF(pais_origen!$N$8:$N$212, $A2, pais_origen!E$8:E$212) -> 816828 | F2: =SUMIF(pais_origen!$N$8:$N$212, $A2, pais_origen!F$8:F$212) -> 0 | G2: =SUMIF(pais_origen!$N$8:$N$212, $A2, pais_origen!G$8:G$212) -> 581131 | H2: =SUMIF(pais_origen!$N$8:$N$212, $A2, pais_origen!H$8:H$212) -> 16719267 | I2: =SUMIF(pais_origen!$N$8:$N$212, $A2, pais_origen!I$8:I$212) -> 534293 | ... L2: =SUMIF(pais_origen!$N$8:$N$212, $A2, pais_origen!L$8:L$212) -> 24688379
A3: Southern Africa | B3: =SUMIF(pais_origen!$N$8:$N$212, $A3, pais_origen!B$8:B$212) -> 1016547 | C3: =SUMIF(pais_origen!$N$8:$N$212, $A3, pais_origen!C$8:C$212) -> 83 | D3: =SUMIF(pais_origen!$N$8:$N$212, $A3, pais_origen!D$8:D$212) -> 1016630 | E3: =SUMIF(pais_origen!$N$8:$N$212, $A3, pais_origen!E$8:E$212) -> 212366 | F3: =SUMIF(pais_origen!$N$8:$N$212, $A3, pais_origen!F$8:F$212) -> 0 | G3: =SUMIF(pais_origen!$N$8:$N$212, $A3, pais_origen!G$8:G$212) -> 1808 | H3: =SUMIF(pais_origen!$N$8:$N$212, $A3, pais_origen!H$8:H$212) -> 6834554 | I3: =SUMIF(pais_origen!$N$8:$N$212, $A3, pais_origen!I$8:I$212) -> 2114080 | ... L3: =SUMIF(pais_origen!$N$8:$N$212, $A3, pais_origen!L$8:L$212) -> 10211958
A4: West and Central Africa | B4: =SUMIF(pais_origen!$N$8:$N$212, $A4, pais_origen!B$8:B$212) -> 1740705 | C4: =SUMIF(pais_origen!$N$8:$N$212, $A4, pais_origen!C$8:C$212) -> 1177 | D4: =SUMIF(pais_origen!$N$8:$N$212, $A4, pais_origen!D$8:D$212) -> 1741882 | E4: =SUMIF(pais_origen!$N$8:$N$212, $A4, pais_origen!E$8:E$212) -> 417331 | F4: =SUMIF(pais_origen!$N$8:$N$212, $A4, pais_origen!F$8:F$212) -> 0 | G4: =SUMIF(pais_origen!$N$8:$N$212, $A4, pais_origen!G$8:G$212) -> 48855 | H4: =SUMIF(pais_origen!$N$8:$N$212, $A4, pais_origen!H$8:H$212) -> 7887599 | I4: =SUMIF(pais_origen!$N$8:$N$212, $A4, pais_origen!I$8:I$212) -> 455882 | ... L4: =SUMIF(pais_origen!$N$8:$N$212, $A4, pais_origen!L$8:L$212) -> 10714579
A5: Sub-Saharan Africa | B5: =SUM(B2:B4) -> 8695671 | C5: =SUM(C2:C4) -> 1454 | D5: =SUM(D2:D4) -> 8697125 | E5: =SUM(E2:E4) -> 1446525 | F5: =SUM(F2:F4) -> 0 | G5: =SUM(G2:G4) -> 631794 | H5: =SUM(H2:H4) -> 31441420 | I5: =SUM(I2:I4) -> 3104255 | ... L5: =SUM(L2:L4) -> 45614916
A6: Americas | B6: =SUMIF(pais_origen!$N$8:$N$212, $A6, pais_origen!B$8:B$212) -> 747817 | C6: =SUMIF(pais_origen!$N$8:$N$212, $A6, pais_origen!C$8:C$212) -> 113697 | D6: =SUMIF(pais_origen!$N$8:$N$212, $A6, pais_origen!D$8:D$212) -> 861514 | E6: =SUMIF(pais_origen!$N$8:$N$212, $A6, pais_origen!E$8:E$212) -> 3330751 | F6: =SUMIF(pais_origen!$N$8:$N$212, $A6, pais_origen!F$8:F$212) -> 5755363 | G6: =SUMIF(pais_origen!$N$8:$N$212, $A6, pais_origen!G$8:G$212) -> 5 | H6: =SUMIF(pais_origen!$N$8:$N$212, $A6, pais_origen!H$8:H$212) -> 7813275 | I6: =SUMIF(pais_origen!$N$8:$N$212, $A6, pais_origen!I$8:I$212) -> 0 | ... L6: =SUMIF(pais_origen!$N$8:$N$212, $A6, pais_origen!L$8:L$212) -> 21989440
A7: Asia and the Pacific | B7: =SUMIF(pais_origen!$N$8:$N$212, $A7, pais_origen!B$8:B$212) -> 4614895 | C7: =SUMIF(pais_origen!$N$8:$N$212, $A7, pais_origen!C$8:C$212) -> 3771087 | D7: =SUMIF(pais_origen!$N$8:$N$212, $A7, pais_origen!D$8:D$212) -> 8385982 | E7: =SUMIF(pais_origen!$N$8:$N$212, $A7, pais_origen!E$8:E$212) -> 993931 | F7: =SUMIF(pais_origen!$N$8:$N$212, $A7, pais_origen!F$8:F$212) -> 0 | G7: =SUMIF(pais_origen!$N$8:$N$212, $A7, pais_origen!G$8:G$212) -> 57951 | H7: =SUMIF(pais_origen!$N$8:$N$212, $A7, pais_origen!H$8:H$212) -> 6039085 | I7: =SUMIF(pais_origen!$N$8:$N$212, $A7, pais_origen!I$8:I$212) -> 449303 | ... L7: =SUMIF(pais_origen!$N$8:$N$212, $A7, pais_origen!L$8:L$212) -> 16146464
A8: Europe | B8: =SUMIF(pais_origen!$N$8:$N$212, $A8, pais_origen!B$8:B$212) -> 4576966 | C8: =SUMIF(pais_origen!$N$8:$N$212, $A8, pais_origen!C$8:C$212) -> 1904559 | D8: =SUMIF(pais_origen!$N$8:$N$212, $A8, pais_origen!D$8:D$212) -> 6481525 | E8: =SUMIF(pais_origen!$N$8:$N$212, $A8, pais_origen!E$8:E$212) -> 431625 | F8: =SUMIF(pais_origen!$N$8:$N$212, $A8, pais_origen!F$8:F$212) -> 0 | G8: =SUMIF(pais_origen!$N$8:$N$212, $A8, pais_origen!G$8:G$212) -> 324590 | H8: =SUMIF(pais_origen!$N$8:$N$212, $A8, pais_origen!H$8:H$212) -> 4943593 | I8: =SUMIF(pais_origen!$N$8:$N$212, $A8, pais_origen!I$8:I$212) -> 1318794 | ... L8: =SUMIF(pais_origen!$N$8:$N$212, $A8, pais_origen!L$8:L$212) -> 14490325
A9: Middle East and North Africa | B9: =SUMIF(pais_origen!$N$8:$N$212, $A9, pais_origen!B$8:B$212) -> 6971936 | C9: =SUMIF(pais_origen!$N$8:$N$212, $A9, pais_origen!C$8:C$212) -> 8162 | D9: =SUMIF(pais_origen!$N$8:$N$212, $A9, pais_origen!D$8:D$212) -> 6980098 | E9: =SUMIF(pais_origen!$N$8:$N$212, $A9, pais_origen!E$8:E$212) -> 554773 | F9: =SUMIF(pais_origen!$N$8:$N$212, $A9, pais_origen!F$8:F$212) -> 0 | G9: =SUMIF(pais_origen!$N$8:$N$212, $A9, pais_origen!G$8:G$212) -> 37728 | H9: =SUMIF(pais_origen!$N$8:$N$212, $A9, pais_origen!H$8:H$212) -> 13013994 | I9: =SUMIF(pais_origen!$N$8:$N$212, $A9, pais_origen!I$8:I$212) -> 219712 | ... L9: =SUMIF(pais_origen!$N$8:$N$212, $A9, pais_origen!L$8:L$212) -> 20844311
A10: Various/Stateless | B10: =pais_origen!B213-SUM(B5:B9) -> 158079 | C10: =pais_origen!C213-SUM(C5:C9) -> 73085 | D10: =pais_origen!D213-SUM(D5:D9) -> 231164 | E10: =pais_origen!E213-SUM(E5:E9) -> 100894 | F10: =pais_origen!F213-SUM(F5:F9) -> 0 | G10: =pais_origen!G213-SUM(G5:G9) -> 6 | H10: =pais_origen!H213-SUM(H5:H9) -> 0 | I10: =pais_origen!I213-SUM(I5:I9) -> 0 | ... L10: =pais_origen!L213-SUM(L5:L9) -> 3537393
A11: Total | B11: =SUM(B5:B10) -> 25765364 | C11: =SUM(C5:C10) -> 5872044 | D11: =SUM(D5:D10) -> 31637408 | E11: =SUM(E5:E10) -> 6858499 | F11: =SUM(F5:F10) -> 5755363 | G11: =SUM(G5:G10) -> 1052074 | H11: =SUM(H5:H10) -> 63251367 | I11: =SUM(I5:I10) -> 5092064 | ... L11: =SUM(L5:L10) -> 122622849

Sheet pais_origen_UN_regions
A1: UN major regions | B1: Refugees 2 | C1: People in refugee-like situations3 | D1: Total refugees and people in refugee-like situations | E1: Asylum-seekers (pending cases)4 | F1: Other people in need of international protection5 | G1: Returned refugees6 | H1: IDPs of concern to UNHCR7 | I1: Returned IDPs8 | J1: Persons under UNHCR's statelessness mandate9 | K1: Others of concern to UNHCR10 | L1: Total population of concern
A2: Africa | B2: =SUMIF(pais_origen!$O$8:$O$212, $A2, pais_origen!B$8:B$212) -> 8883655 | C2: =SUMIF(pais_origen!$O$8:$O$212, $A2, pais_origen!C$8:C$212) -> 2350 | D2: =SUMIF(pais_origen!$O$8:$O$212, $A2, pais_origen!D$8:D$212) -> 8886005 | E2: =SUMIF(pais_origen!$O$8:$O$212, $A2, pais_origen!E$8:E$212) -> 1556386 | F2: =SUMIF(pais_origen!$O$8:$O$212, $A2, pais_origen!F$8:F$212) -> 0 | G2: =SUMIF(pais_origen!$O$8:$O$212, $A2, pais_origen!G$8:G$212) -> 631805 | H2: =SUMIF(pais_origen!$O$8:$O$212, $A2, pais_origen!H$8:H$212) -> 31567222 | I2: =SUMIF(pais_origen!$O$8:$O$212, $A2, pais_origen!I$8:I$212) -> 3141354 | ... L2: =SUMIF(pais_origen!$O$8:$O$212, $A2, pais_origen!L$8:L$212) -> 46077808
A3: Asia | B3: =SUMIF(pais_origen!$O$8:$O$212, $A3, pais_origen!B$8:B$212) -> 11712587 | C3: =SUMIF(pais_origen!$O$8:$O$212, $A3, pais_origen!C$8:C$212) -> 3779378 | D3: =SUMIF(pais_origen!$O$8:$O$212, $A3, pais_origen!D$8:D$212) -> 15491965 | E3: =SUMIF(pais_origen!$O$8:$O$212, $A3, pais_origen!E$8:E$212) -> 1648897 | F3: =SUMIF(pais_origen!$O$8:$O$212, $A3, pais_origen!F$8:F$212) -> 0 | G3: =SUMIF(pais_origen!$O$8:$O$212, $A3, pais_origen!G$8:G$212) -> 95668 | H3: =SUMIF(pais_origen!$O$8:$O$212, $A3, pais_origen!H$8:H$212) -> 19784857 | I3: =SUMIF(pais_origen!$O$8:$O$212, $A3, pais_origen!I$8:I$212) -> 631916 | ... L3: =SUMIF(pais_origen!$O$8:$O$212, $A3, pais_origen!L$8:L$212) -> 37909021
A4: Europe | B4: =SUMIF(pais_origen!$O$8:$O$212, $A4, pais_origen!B$8:B$212) -> 4262383 | C4: =SUMIF(pais_origen!$O$8:$O$212, $A4, pais_origen!C$8:C$212) -> 1903534 | D4: =SUMIF(pais_origen!$O$8:$O$212, $A4, pais_origen!D$8:D$212) -> 6165917 | E4: =SUMIF(pais_origen!$O$8:$O$212, $A4, pais_origen!E$8:E$212) -> 214734 | F4: =SUMIF(pais_origen!$O$8:$O$212, $A4, pais_origen!F$8:F$212) -> 0 | G4: =SUMIF(pais_origen!$O$8:$O$212, $A4, pais_origen!G$8:G$212) -> 324590 | H4: =SUMIF(pais_origen!$O$8:$O$212, $A4, pais_origen!H$8:H$212) -> 3990013 | I4: =SUMIF(pais_origen!$O$8:$O$212, $A4, pais_origen!I$8:I$212) -> 1318794 | ... L4: =SUMIF(pais_origen!$O$8:$O$212, $A4, pais_origen!L$8:L$212) -> 13003771
A5: Latin America | B5: =SUMIF(pais_origen!$O$8:$O$212, $A5, pais_origen!B$8:B$212) -> 706006 | C5: =SUMIF(pais_origen!$O$8:$O$212, $A5, pais_origen!C$8:C$212) -> 26315 | D5: =SUMIF(pais_origen!$O$8:$O$212, $A5, pais_origen!D$8:D$212) -> 732321 | E5: =SUMIF(pais_origen!$O$8:$O$212, $A5, pais_origen!E$8:E$212) -> 3076179 | F5: =SUMIF(pais_origen!$O$8:$O$212, $A5, pais_origen!F$8:F$212) -> 5755363 | G5: =SUMIF(pais_origen!$O$8:$O$212, $A5, pais_origen!G$8:G$212) -> 5 | H5: =SUMIF(pais_origen!$O$8:$O$212, $A5, pais_origen!H$8:H$212) -> 7499374 | I5: =SUMIF(pais_origen!$O$8:$O$212, $A5, pais_origen!I$8:I$212) -> 0 | ... L5: =SUMIF(pais_origen!$O$8:$O$212, $A5, pais_origen!L$8:L$212) -> 21253715
A6: North America and the Caribbean | B6: =SUMIF(pais_origen!$O$8:$O$212, $A6, pais_origen!B$8:B$212) -> 41811 | C6: =SUMIF(pais_origen!$O$8:$O$212, $A6, pais_origen!C$8:C$212) -> 87382 | D6: =SUMIF(pais_origen!$O$8:$O$212, $A6, pais_origen!D$8:D$212) -> 129193 | E6: =SUMIF(pais_origen!$O$8:$O$212, $A6, pais_origen!E$8:E$212) -> 254572 | F6: =SUMIF(pais_origen!$O$8:$O$212, $A6, pais_origen!F$8:F$212) -> 0 | G6: =SUMIF(pais_origen!$O$8:$O$212, $A6, pais_origen!G$8:G$212) -> 0 | H6: =SUMIF(pais_origen!$O$8:$O$212, $A6, pais_origen!H$8:H$212) -> 313901 | I6: =SUMIF(pais_origen!$O$8:$O$212, $A6, pais_origen!I$8:I$212) -> 0 | ... L6: =SUMIF(pais_origen!$O$8:$O$212, $A6, pais_origen!L$8:L$212) -> 735725
A7: Oceania | B7: =SUMIF(pais_origen!$O$8:$O$212, $A7, pais_origen!B$8:B$212) -> 843 | C7: =SUMIF(pais_origen!$O$8:$O$212, $A7, pais_origen!C$8:C$212) -> 0 | D7: =SUMIF(pais_origen!$O$8:$O$212, $A7, pais_origen!D$8:D$212) -> 843 | E7: =SUMIF(pais_origen!$O$8:$O$212, $A7, pais_origen!E$8:E$212) -> 6837 | F7: =SUMIF(pais_origen!$O$8:$O$212, $A7, pais_origen!F$8:F$212) -> 0 | G7: =SUMIF(pais_origen!$O$8:$O$212, $A7, pais_origen!G$8:G$212) -> 0 | H7: =SUMIF(pais_origen!$O$8:$O$212, $A7, pais_origen!H$8:H$212) -> 96000 | I7: =SUMIF(pais_origen!$O$8:$O$212, $A7, pais_origen!I$8:I$212) -> 0 | ... L7: =SUMIF(pais_origen!$O$8:$O$212, $A7, pais_origen!L$8:L$212) -> 105416
A8: Various/Stateless | B8: =pais_origen!B213-SUM(B2:B7) -> 158079 | C8: =pais_origen!C213-SUM(C2:C7) -> 73085 | D8: =pais_origen!D213-SUM(D2:D7) -> 231164 | E8: =pais_origen!E213-SUM(E2:E7) -> 100894 | F8: =pais_origen!F213-SUM(F2:F7) -> 0 | G8: =pais_origen!G213-SUM(G2:G7) -> 6 | H8: =pais_origen!H213-SUM(H2:H7) -> 0 | I8: =pais_origen!I213-SUM(I2:I7) -> 0 | ... L8: =pais_origen!L213-SUM(L2:L7) -> 3537393
A9: Total | B9: =SUM(B2:B8) -> 25765364 | C9: =SUM(C2:C8) -> 5872044 | D9: =SUM(D2:D8) -> 31637408 | E9: =SUM(E2:E8) -> 6858499 | F9: =SUM(F2:F8) -> 5755363 | G9: =SUM(G2:G8) -> 1052074 | H9: =SUM(H2:H8) -> 63251367 | I9: =SUM(I2:I8) -> 5092064 | ... L9: =SUM(L2:L8) -> 122622849

Sheet demografia
A1: Table 6 | Demographic composition by country/territory of asylum and type of population | end-2023
A2: All data are provisional and subject to change.
A3: Data available at: | B3: https://www.unhcr.org/refugee-statistics
A4: * Indicates the proportion of the population type in the country for which the demographic data are available. If the coverage is low (i.e. below 50%), the percentages may not be representative for the total population of concern in the country.
A5: The population for which demographic data is available does not necessarily equal the total population type in the country. See notes in Annex Table 1.
A6: Small values between zero and five have been rounded to multiples of five. Demographic data has been additionally modified so that the data remains additive. A dash ("-") indicates that the value is zero, not available or not applicable.
D8: Female | L8: Male | U8: Coverage*
A9: Country/territory of asylum/residence | B9: Population type1 | C9: Population for which demographic data is available | D9: 0-4 | E9: 5-11 | F9: 12-17 | G9: 0-17 | H9: 18-59 | I9: 60+ | J9: Unknown age | K9: Total | L9: 0-4 | M9: 5-11 | N9: 12-17 | O9: 0-17 | P9: 18-59 | Q9: 60+ | R9: Unknown age | S9: Total | T9: Population of concern to UNHCR, end-2023 | U9: Age and sex | V9: Sex only | W9: ISO code
A10: All | B10: Refugees | C10: =K10+S10 -> 26242920 | D10: =SUMIF($B$18:$B$583,$B10,D$18:D$583) -> 1425602 | E10: =SUMIF($B$18:$B$583,$B10,E$18:E$583) -> 2444869 | F10: =SUMIF($B$18:$B$583,$B10,F$18:F$583) -> 1699112 | G10: =SUMIF($B$18:$B$583,$B10,G$18:G$583) -> 5569583 | H10: =SUMIF($B$18:$B$583,$B10,H$18:H$583) -> 5776545 | I10: =SUMIF($B$18:$B$583,$B10,I$18:I$583) -> 592012 | J10: =SUMIF($B$18:$B$583,$B10,J$18:J$583) -> 1061321 | K10: =SUMIF($B$18:$B$583,$B10,K$18:K$583) -> 12999461 | ... T10: =SUMIF($B$18:$B$583,$B10,T$18:T$583) -> 31637408 | U10: =(S10-R10+K10-J10)/T10 -> 0.76098143 | V10: =(S10+K10)/T10 -> 0.8294902
A11: All | B11: Asylum-seekers | C11: =K11+S11 -> 2719799 | D11: =SUMIF($B$18:$B$583,$B11,D$18:D$583) -> 89810 | E11: =SUMIF($B$18:$B$583,$B11,E$18:E$583) -> 132867 | F11: =SUMIF($B$18:$B$583,$B11,F$18:F$583) -> 90942 | G11: =SUMIF($B$18:$B$583,$B11,G$18:G$583) -> 313619 | H11: =SUMIF($B$18:$B$583,$B11,H$18:H$583) -> 554277 | I11: =SUMIF($B$18:$B$583,$B11,I$18:I$583) -> 35671 | J11: =SUMIF($B$18:$B$583,$B11,J$18:J$583) -> 189956 | K11: =SUMIF($B$18:$B$583,$B11,K$18:K$583) -> 1093523 | ... T11: =SUMIF($B$18:$B$583,$B11,T$18:T$583) -> 6858499 | U11: =(S11-R11+K11-J11)/T11 -> 0.30921766 | V11: =(S11+K11)/T11 -> 0.39655893
A12: All | B12: Other people in need of international protection | C12: =K12+S12 -> 5102655 | D12: =SUMIF($B$18:$B$583,$B12,D$18:D$583) -> 115318 | E12: =SUMIF($B$18:$B$583,$B12,E$18:E$583) -> 66785 | F12: =SUMIF($B$18:$B$583,$B12,F$18:F$583) -> 372028 | G12: =SUMIF($B$18:$B$583,$B12,G$18:G$583) -> 554131 | H12: =SUMIF($B$18:$B$583,$B12,H$18:H$583) -> 1396637 | I12: =SUMIF($B$18:$B$583,$B12,I$18:I$583) -> 84065 | J12: =SUMIF($B$18:$B$583,$B12,J$18:J$583) -> 607315 | K12: =SUMIF($B$18:$B$583,$B12,K$18:K$583) -> 2642148 | ... T12: =SUMIF($B$18:$B$583,$B12,T$18:T$583) -> 5755363 | U12: =(S12-R12+K12-J12)/T12 -> 0.68469148 | V12: =(S12+K12)/T12 -> 0.88659134
A13: All | B13: IDPs | C13: =K13+S13 -> 41744003 | D13: =SUMIF($B$18:$B$583,$B13,D$18:D$583) -> 2024378 | E13: =SUMIF($B$18:$B$583,$B13,E$18:E$583) -> 3243605 | F13: =SUMIF($B$18:$B$583,$B13,F$18:F$583) -> 2536557 | G13: =SUMIF($B$18:$B$583,$B13,G$18:G$583) -> 7804540 | H13: =SUMIF($B$18:$B$583,$B13,H$18:H$583) -> 8928840 | I13: =SUMIF($B$18:$B$583,$B13,I$18:I$583) -> 1706046 | J13: =SUMIF($B$18:$B$583,$B13,J$18:J$583) -> 2692038 | K13: =SUMIF($B$18:$B$583,$B13,K$18:K$583) -> 21131464 | ... T13: =SUMIF($B$18:$B$583,$B13,T$18:T$583) -> 63251367 | U13: =(S13-R13+K13-J13)/T13 -> 0.57493195 | V13: =(S13+K13)/T13 -> 0.65996997
A14: All | B14: Stateless persons | C14: =K14+S14 -> 2121441 | D14: =SUMIF($B$18:$B$583,$B14,D$18:D$583) -> 155147 | E14: =SUMIF($B$18:$B$583,$B14,E$18:E$583) -> 149007 | F14: =SUMIF($B$18:$B$583,$B14,F$18:F$583) -> 108118 | G14: =SUMIF($B$18:$B$583,$B14,G$18:G$583) -> 412272 | H14: =SUMIF($B$18:$B$583,$B14,H$18:H$583) -> 563177 | I14: =SUMIF($B$18:$B$583,$B14,I$18:I$583) -> 70095 | J14: =SUMIF($B$18:$B$583,$B14,J$18:J$583) -> 56528 | K14: =SUMIF($B$18:$B$583,$B14,K$18:K$583) -> 1102072 | ... T14: =SUMIF($B$18:$B$583,$B14,T$18:T$583) -> 3030524 | U14: =(S14-R14+K14-J14)/T14 -> 0.66246992 | V14: =(S14+K14)/T14 -> 0.70002448
A15: All | B15: Others of concern | C15: =K15+S15 -> 3778063 | D15: =SUMIF($B$18:$B$583,$B15,D$18:D$583) -> 111644 | E15: =SUMIF($B$18:$B$583,$B15,E$18:E$583) -> 168545 | F15: =SUMIF($B$18:$B$583,$B15,F$18:F$583) -> 267976 | G15: =SUMIF($B$18:$B$583,$B15,G$18:G$583) -> 548165 | H15: =SUMIF($B$18:$B$583,$B15,H$18:H$583) -> 1261576 | I15: =SUMIF($B$18:$B$583,$B15,I$18:I$583) -> 9143 | J15: =SUMIF($B$18:$B$583,$B15,J$18:J$583) -> 218917 | K15: =SUMIF($B$18:$B$583,$B15,K$18:K$583) -> 2037801 | ... T15: =SUMIF($B$18:$B$583,$B15,T$18:T$583) -> 5945550 | U15: =(S15-R15+K15-J15)/T15 -> 0.56325605 | V15: =(S15+K15)/T15 -> 0.63544382
A16: All | B16: Refugee returnees | C16: =K16+S16 -> 150628 | D16: =SUMIF($B$18:$B$583,$B16,D$18:D$583) -> 13932 | E16: =SUMIF($B$18:$B$583,$B16,E$18:E$583) -> 23327 | F16: =SUMIF($B$18:$B$583,$B16,F$18:F$583) -> 8738 | G16: =SUMIF($B$18:$B$583,$B16,G$18:G$583) -> 45997 | H16: =SUMIF($B$18:$B$583,$B16,H$18:H$583) -> 30131 | I16: =SUMIF($B$18:$B$583,$B16,I$18:I$583) -> 1885 | J16: =SUMIF($B$18:$B$583,$B16,J$18:J$583) -> 10 | K16: =SUMIF($B$18:$B$583,$B16,K$18:K$583) -> 78023 | ... T16: =SUMIF($B$18:$B$583,$B16,T$18:T$583) -> 1052074 | U16: =(S16-R16+K16-J16)/T16 -> 0.14314297 | V16: =(S16+K16)/T16 -> 0.14317244
A17: All | B17: IDP Returnees | C17: =K17+S17 -> 806347 | D17: =SUMIF($B$18:$B$583,$B17,D$18:D$583) -> 36670 | E17: =SUMIF($B$18:$B$583,$B17,E$18:E$583) -> 38227 | F17: =SUMIF($B$18:$B$583,$B17,F$18:F$583) -> 45274 | G17: =SUMIF($B$18:$B$583,$B17,G$18:G$583) -> 120171 | H17: =SUMIF($B$18:$B$583,$B17,H$18:H$583) -> 156388 | I17: =SUMIF($B$18:$B$583,$B17,I$18:I$583) -> 31673 | J17: =SUMIF($B$18:$B$583,$B17,J$18:J$583) -> 113855 | K17: =SUMIF($B$18:$B$583,$B17,K$18:K$583) -> 422087 | ... T17: =SUMIF($B$18:$B$583,$B17,T$18:T$583) -> 5092064 | U17: =(S17-R17+K17-J17)/T17 -> 0.11571575 | V17: =(S17+K17)/T17 -> 0.15835367
A18: Afghanistan | B18: Asylum-seekers | C18: 250 | D18: 27 | E18: 41 | F18: 8 | G18: 76 | H18: 51 | I18: 0 | J18: 0 | K18: 127 | L18: 8 | M18: 32 | N18: 28 | O18: 68 | P18: 50 | Q18: 5 | R18: 0 | S18: 123 | T18: 250 | U18: 1 | V18: 1 | W18: AFG
A19: Afghanistan | B19: IDP Returnees | C19: 31605 | D19: 2845 | E19: 4527 | F19: 3151 | G19: 10523 | H19: 5638 | I19: 702 | J19: 0 | K19: 16863 | L19: 2808 | M19: 4383 | N19: 2494 | O19: 9685 | P19: 4427 | Q19: 630 | R19: 0 | S19: 14742 | T19: 31605 | U19: 1 | V19: 1 | W19: AFG
A20: Afghanistan | B20: IDPs | C20: 3222397 | D20: 298053 | E20: 457879 | F20: 298053 | G20: 1053985 | H20: 609061 | I20: 73433 | J20: 0 | K20: 1736479 | L20: 289409 | M20: 436275 | N20: 233256 | O20: 958940 | P20: 462184 | Q20: 64794 | R20: 0 | S20: 1485918 | T20: 3222397 | U20: 1 | V20: 1 | W20: AFG
A21: Afghanistan | B21: Others of concern | C21: 33712 | D21: 3296 | E21: 4144 | F21: 2251 | G21: 9691 | H21: 7709 | I21: 373 | J21: 0 | K21: 17773 | L21: 3305 | M21: 3584 | N21: 1984 | O21: 8873 | P21: 6413 | Q21: 653 | R21: 0 | S21: 15939 | T21: 33712 | U21: 1 | V21: 1 | W21: AFG
A22: Afghanistan | B22: Refugee returnees | C22: 54868 | D22: 4947 | E22: 6818 | F22: 3408 | G22: 15173 | H22: 10376 | I22: 604 | J22: 0 | K22: 26153 | L22: 4849 | M22: 7106 | N22: 3389 | O22: 15344 | P22: 12265 | Q22: 1106 | R22: 0 | S22: 28715 | T22: 57530 | U22: 0.95372849 | V22: 0.95372849 | W22: AFG
A23: Afghanistan | B23: Refugees | C23: 34826 | D23: 3649 | E23: 4034 | F23: 2384 | G23: 10067 | H23: 7640 | I23: 776 | J23: 0 | K23: 18483 | L23: 3287 | M23: 4138 | N23: 2106 | O23: 9531 | P23: 5823 | Q23: 989 | R23: 0 | S23: 16343 | T23: 34826 | U23: 1 | V23: 1 | W23: AFG
A24: Albania | B24: Asylum-seekers | C24: 0 | D24: 0 | E24: 0 | F24: 0 | G24: 0 | H24: 0 | I24: 0 | J24: 0 | K24: 0 | L24: 0 | M24: 0 | N24: 0 | O24: 0 | P24: 0 | Q24: 0 | R24: 0 | S24: 0 | T24: 8 | U24: 0 | V24: 0 | W24: ALB
A25: Albania | B25: Others of concern | C25: 0 | D25: 0 | E25: 0 | F25: 0 | G25: 0 | H25: 0 | I25: 0 | J25: 0 | K25: 0 | L25: 0 | M25: 0 | N25: 0 | O25: 0 | P25: 0 | Q25: 0 | R25: 0 | S25: 0 | T25: 6 | U25: 0 | V25: 0 | W25: ALB
A26: Albania | B26: Refugees | C26: 0 | D26: 0 | E26: 0 | F26: 0 | G26: 0 | H26: 0 | I26: 0 | J26: 0 | K26: 0 | L26: 0 | M26: 0 | N26: 0 | O26: 0 | P26: 0 | Q26: 0 | R26: 0 | S26: 0 | T26: 5079 | U26: 0 | V26: 0 | W26: ALB
A27: Albania | B27: Stateless persons | C27: 0 | D27: 0 | E27: 0 | F27: 0 | G27: 0 | H27: 0 | I27: 0 | J27: 0 | K27: 0 | L27: 0 | M27: 0 | N27: 0 | O27: 0 | P27: 0 | Q27: 0 | R27: 0 | S27: 0 | T27: 2018 | U27: 0 | V27: 0 | W27: ALB
A28: Algeria | B28: Asylum-seekers | C28: 3601 | D28: 223 | E28: 93 | F28: 83 | G28: 399 | H28: 828 | I28: 0 | J28: 0 | K28: 1227 | L28: 223 | M28: 85 | N28: 142 | O28: 450 | P28: 1924 | Q28: 0 | R28: 0 | S28: 2374 | T28: 3601 | U28: 1 | V28: 1 | W28: DZA
A29: Algeria | B29: Refugees | C29: 8590 | D29: 468 | E29: 730 | F29: 449 | G29: 1647 | H29: 1638 | I29: 71 | J29: 0 | K29: 3356 | L29: 487 | M29: 807 | N29: 498 | O29: 1792 | P29: 3350 | Q29: 92 | R29: 0 | S29: 5234 | T29: 98590 | U29: 0.087128512 | V29: 0.087128512 | W29: DZA
... A583: Zimbabwe | B583: Refugees | C583: 10114 | D583: 684 | E583: 963 | F583: 724 | G583: 2371 | H583: 2266 | I583: 82 | J583: 0 | K583: 4719 | L583: 682 | M583: 985 | N583: 821 | O583: 2488 | P583: 2829 | Q583: 78 | R583: 0 | S583: 5395 | T583: 10114 | U583: 1 | V583: 1 | W583: ZWE
A584: Total | C584: =SUM(C18:C583) -> 82665856 | D584: =SUM(D18:D583) -> 3972501 | E584: =SUM(E18:E583) -> 6267232 | F584: =SUM(F18:F583) -> 5128745 | G584: =SUM(G18:G583) -> 15368478 | H584: =SUM(H18:H583) -> 18667571 | I584: =SUM(I18:I583) -> 2530590 | J584: =SUM(J18:J583) -> 4939940 | ... T584: =SUM(T18:T583) -> 122622849 | U584: =(S584-R584+K584-J584)/T584 -> 0.59204672 | V584: =(S584+K584)/T584 -> 0.67414725
A586: Notes
A587: 1 Refugees includes people in refugee-like situations
